<robot name="pendulum">
    <link name="base_link">
    </link>
    <!-- =========== First Rod =========== -->
    <link name="first_rod">
    <visual>
        <origin rpy="0 0 0" xyz="0 0 0.3" />
        <geometry>
            <box size="0.1 0.1 0.6" />
        </geometry>
    </visual>
    <collision>
        <origin rpy="0 0 0" xyz="0 0 0.3" />
        <geometry>
            <box size="0.1 0.1 0.6" />
        </geometry>
    </collision>
    <inertial>
        <origin xyz="0 0 0" rpy="0 0 0"/>
        <mass value="1"/>
        <inertia
            ixx="1.0" ixy="0.0" ixz="0.0"
            iyy="1.0" iyz="0.0"
            izz="1.0"/>
    </inertial>
    </link>
    <joint name="revolute" type="revolute">
        <parent link="base_link" />
        <child link="first_rod" />
        <origin xyz="0 0 0" />
        <axis xyz="1 0 0" />
        <limit effort="0" velocity="0.1" lower="-3.14" upper="3.14" />
    </joint>
    <!-- =========== Second Rod =========== -->
</robot>